2014-02-04T00:18:26.168411+00:00 app[web.1]:   File "/app/.heroku/python/lib/python2.7/site-packages/django/utils/importlib.py", line 40, in import_module
2014-02-04T00:18:26.168411+00:00 app[web.1]:     module = import_module(module_path)
2014-02-04T00:18:26.168411+00:00 app[web.1]:   File "/app/.heroku/python/lib/python2.7/site-packages/django/utils/module_loading.py", line 21, in import_by_path
2014-02-04T00:18:26.168177+00:00 app[web.1]:     mw_class = import_by_path(middleware_path)
2014-02-04T00:18:26.168571+00:00 app[web.1]:     self.db_table = truncate_name(self.db_table, connection.ops.max_name_length())
2014-02-04T00:18:26.168571+00:00 app[web.1]:   File "/app/.heroku/python/lib/python2.7/site-packages/django/db/__init__.py", line 34, in __getattr__
2014-02-04T00:18:26.168571+00:00 app[web.1]:     return getattr(connections[DEFAULT_DB_ALIAS], item)
2014-02-04T00:18:26.168996+00:00 app[web.1]:   File "/app/.heroku/python/lib/python2.7/site-packages/django/db/utils.py", line 113, in load_backend
2014-02-04T00:18:26.168411+00:00 app[web.1]:   File "/app/.heroku/python/lib/python2.7/site-packages/django/contrib/auth/models.py", line 48, in <module>
2014-02-04T00:18:26.168571+00:00 app[web.1]:     value.contribute_to_class(cls, name)
2014-02-04T00:18:26.168411+00:00 app[web.1]:     from django.contrib.auth.backends import RemoteUserBackend
2014-02-04T00:18:26.168996+00:00 app[web.1]:   File "/app/.heroku/python/lib/python2.7/site-packages/django/db/backends/postgresql_psycopg2/base.py", line 25, in <module>
2014-02-04T00:18:26.168996+00:00 app[web.1]:     return import_module('%s.base' % backend_name)
2014-02-04T00:18:26.168996+00:00 app[web.1]:   File "/app/.heroku/python/lib/python2.7/site-packages/django/utils/importlib.py", line 40, in import_module
2014-02-04T00:18:26.168996+00:00 app[web.1]:     __import__(name)
2014-02-04T00:18:26.168571+00:00 app[web.1]:   File "/app/.heroku/python/lib/python2.7/site-packages/django/db/models/base.py", line 96, in __new__
2014-02-04T00:18:26.168411+00:00 app[web.1]:     class Permission(models.Model):
2014-02-04T00:18:26.168996+00:00 app[web.1]:     raise ImproperlyConfigured("Error loading psycopg2 module: %s" % e)
2014-02-04T00:18:26.168996+00:00 app[web.1]: ImproperlyConfigured: Error loading psycopg2 module: No module named psycopg2
2014-02-04T00:18:26.168571+00:00 app[web.1]:   File "/app/.heroku/python/lib/python2.7/site-packages/django/db/models/base.py", line 264, in add_to_class
2014-02-04T00:18:26.168571+00:00 app[web.1]:     new_class.add_to_class('_meta', Options(meta, **kwargs))
2014-02-04T00:18:26.168571+00:00 app[web.1]:   File "/app/.heroku/python/lib/python2.7/site-packages/django/db/utils.py", line 198, in __getitem__
2014-02-04T00:18:26.168571+00:00 app[web.1]:     backend = load_backend(db['ENGINE'])
2014-02-04T00:18:26.182630+00:00 heroku[router]: at=info method=GET path=/favicon.ico host=rg3915-wttd.herokuapp.com request_id=3773d4cc-6158-4d13-8bfd-0afcbed7c650 fwd="177.81.22.105" dyno=web.1 connect=6ms service=11ms status=500 bytes=135
2014-02-04T00:17:07.668517+00:00 heroku[router]: at=info method=GET path=/ host=rg3915-wttd.herokuapp.com request_id=d1adc01e-4245-46c1-91de-f475efc7fba1 fwd="177.81.22.105" dyno=web.1 connect=78ms service=285ms status=500 bytes=135
2014-02-04T00:32:51.106154+00:00 heroku[router]: at=info method=GET path=/ host=rg3915-wttd.herokuapp.com request_id=71c85b58-f2d7-4203-a75a-d488dc90d551 fwd="177.81.22.105" dyno=web.1 connect=6ms service=9ms status=500 bytes=135
2014-02-04T00:32:51.096483+00:00 app[web.1]:     return self.application(environ, start_response)
2014-02-04T00:32:51.096483+00:00 app[web.1]: 2014-02-04 00:32:51 [7] [ERROR] Error handling request
2014-02-04T00:32:51.096483+00:00 app[web.1]: Traceback (most recent call last):
2014-02-04T00:32:51.096483+00:00 app[web.1]:   File "/app/.heroku/python/lib/python2.7/site-packages/gunicorn/workers/sync.py", line 131, in handle_request
2014-02-04T00:32:51.096483+00:00 app[web.1]:     respiter = self.wsgi(environ, resp.start_response)
2014-02-04T00:32:51.096483+00:00 app[web.1]:   File "/app/.heroku/python/lib/python2.7/site-packages/dj_static.py", line 59, in __call__
2014-02-04T00:32:51.096483+00:00 app[web.1]:   File "/app/.heroku/python/lib/python2.7/site-packages/django/core/handlers/wsgi.py", line 187, in __call__
2014-02-04T00:32:51.096483+00:00 app[web.1]:     self.load_middleware()
2014-02-04T00:32:51.096711+00:00 app[web.1]:   File "/app/.heroku/python/lib/python2.7/site-packages/django/contrib/auth/middleware.py", line 3, in <module>
2014-02-04T00:32:51.096711+00:00 app[web.1]:     from django.contrib.auth.backends import RemoteUserBackend
2014-02-04T00:32:51.096711+00:00 app[web.1]:   File "/app/.heroku/python/lib/python2.7/site-packages/django/contrib/auth/backends.py", line 3, in <module>
2014-02-04T00:32:51.096483+00:00 app[web.1]:   File "/app/.heroku/python/lib/python2.7/site-packages/django/core/handlers/base.py", line 47, in load_middleware
2014-02-04T00:32:51.096483+00:00 app[web.1]:     mw_class = import_by_path(middleware_path)
2014-02-04T00:32:51.096711+00:00 app[web.1]:   File "/app/.heroku/python/lib/python2.7/site-packages/django/utils/module_loading.py", line 21, in import_by_path
2014-02-04T00:32:51.096879+00:00 app[web.1]:     new_class.add_to_class('_meta', Options(meta, **kwargs))
2014-02-04T00:32:51.096879+00:00 app[web.1]:   File "/app/.heroku/python/lib/python2.7/site-packages/django/db/models/base.py", line 264, in add_to_class
2014-02-04T00:32:51.096879+00:00 app[web.1]:     value.contribute_to_class(cls, name)
2014-02-04T00:32:51.096711+00:00 app[web.1]:     __import__(name)
2014-02-04T00:32:51.096711+00:00 app[web.1]:     module = import_module(module_path)
2014-02-04T00:32:51.096711+00:00 app[web.1]:   File "/app/.heroku/python/lib/python2.7/site-packages/django/utils/importlib.py", line 40, in import_module
2014-02-04T00:32:51.096879+00:00 app[web.1]:   File "/app/.heroku/python/lib/python2.7/site-packages/django/db/models/base.py", line 96, in __new__
2014-02-04T00:32:51.096879+00:00 app[web.1]:     self.db_table = truncate_name(self.db_table, connection.ops.max_name_length())
2014-02-04T00:32:51.096711+00:00 app[web.1]:     from django.contrib.auth.models import Permission
2014-02-04T00:32:51.096711+00:00 app[web.1]:   File "/app/.heroku/python/lib/python2.7/site-packages/django/contrib/auth/models.py", line 48, in <module>
2014-02-04T00:32:51.096711+00:00 app[web.1]:     class Permission(models.Model):
2014-02-04T00:32:51.096879+00:00 app[web.1]:     backend = load_backend(db['ENGINE'])
2014-02-04T00:32:51.097329+00:00 app[web.1]:   File "/app/.heroku/python/lib/python2.7/site-packages/django/db/utils.py", line 113, in load_backend
2014-02-04T00:32:51.097329+00:00 app[web.1]:     return import_module('%s.base' % backend_name)
2014-02-04T00:32:51.097329+00:00 app[web.1]:   File "/app/.heroku/python/lib/python2.7/site-packages/django/utils/importlib.py", line 40, in import_module
2014-02-04T00:32:51.097329+00:00 app[web.1]:     __import__(name)
2014-02-04T00:32:51.096879+00:00 app[web.1]:   File "/app/.heroku/python/lib/python2.7/site-packages/django/db/models/options.py", line 124, in contribute_to_class
2014-02-04T00:32:51.096879+00:00 app[web.1]:   File "/app/.heroku/python/lib/python2.7/site-packages/django/db/__init__.py", line 34, in __getattr__
2014-02-04T00:32:51.096879+00:00 app[web.1]:     return getattr(connections[DEFAULT_DB_ALIAS], item)
2014-02-04T00:32:51.097329+00:00 app[web.1]:     raise ImproperlyConfigured("Error loading psycopg2 module: %s" % e)
2014-02-04T00:32:51.097329+00:00 app[web.1]: ImproperlyConfigured: Error loading psycopg2 module: No module named psycopg2
2014-02-04T00:32:51.096879+00:00 app[web.1]:   File "/app/.heroku/python/lib/python2.7/site-packages/django/db/utils.py", line 198, in __getitem__
2014-02-04T00:32:51.097329+00:00 app[web.1]:   File "/app/.heroku/python/lib/python2.7/site-packages/django/db/backends/postgresql_psycopg2/base.py", line 25, in <module>
2014-02-04T00:32:51.464105+00:00 heroku[router]: at=info method=GET path=/favicon.ico host=rg3915-wttd.herokuapp.com request_id=5c7e9640-59c6-459c-a301-eb50d1956eec fwd="177.81.22.105" dyno=web.1 connect=7ms service=7ms status=500 bytes=135
2014-02-04T00:32:51.455052+00:00 app[web.1]: 2014-02-04 00:32:51 [7] [ERROR] Error handling request
2014-02-04T00:32:51.455052+00:00 app[web.1]: Traceback (most recent call last):
2014-02-04T00:32:51.455052+00:00 app[web.1]:   File "/app/.heroku/python/lib/python2.7/site-packages/gunicorn/workers/sync.py", line 131, in handle_request
2014-02-04T00:32:51.455052+00:00 app[web.1]:     respiter = self.wsgi(environ, resp.start_response)
2014-02-04T00:32:51.455052+00:00 app[web.1]:   File "/app/.heroku/python/lib/python2.7/site-packages/dj_static.py", line 59, in __call__
2014-02-04T00:32:51.455052+00:00 app[web.1]:     return self.application(environ, start_response)
2014-02-04T00:32:51.455052+00:00 app[web.1]:   File "/app/.heroku/python/lib/python2.7/site-packages/django/core/handlers/wsgi.py", line 187, in __call__
2014-02-04T00:32:51.455052+00:00 app[web.1]:     self.load_middleware()
2014-02-04T00:32:51.455052+00:00 app[web.1]:   File "/app/.heroku/python/lib/python2.7/site-packages/django/core/handlers/base.py", line 47, in load_middleware
2014-02-04T00:32:51.455052+00:00 app[web.1]:     mw_class = import_by_path(middleware_path)
2014-02-04T00:32:51.455231+00:00 app[web.1]:   File "/app/.heroku/python/lib/python2.7/site-packages/django/utils/module_loading.py", line 21, in import_by_path
2014-02-04T00:32:51.455231+00:00 app[web.1]:     __import__(name)
2014-02-04T00:32:51.455231+00:00 app[web.1]:   File "/app/.heroku/python/lib/python2.7/site-packages/django/utils/importlib.py", line 40, in import_module
2014-02-04T00:32:51.455231+00:00 app[web.1]:   File "/app/.heroku/python/lib/python2.7/site-packages/django/contrib/auth/middleware.py", line 3, in <module>
2014-02-04T00:32:51.455231+00:00 app[web.1]:     from django.contrib.auth.backends import RemoteUserBackend
2014-02-04T00:32:51.455231+00:00 app[web.1]:   File "/app/.heroku/python/lib/python2.7/site-packages/django/contrib/auth/backends.py", line 3, in <module>
2014-02-04T00:32:51.455231+00:00 app[web.1]:     class Permission(models.Model):
2014-02-04T00:32:51.455386+00:00 app[web.1]:     value.contribute_to_class(cls, name)
2014-02-04T00:32:51.455386+00:00 app[web.1]:   File "/app/.heroku/python/lib/python2.7/site-packages/django/db/models/options.py", line 124, in contribute_to_class
2014-02-04T00:32:51.455386+00:00 app[web.1]:     self.db_table = truncate_name(self.db_table, connection.ops.max_name_length())
2014-02-04T00:32:51.455386+00:00 app[web.1]:   File "/app/.heroku/python/lib/python2.7/site-packages/django/db/__init__.py", line 34, in __getattr__
2014-02-04T00:32:51.455231+00:00 app[web.1]:     from django.contrib.auth.models import Permission
2014-02-04T00:32:51.455231+00:00 app[web.1]:   File "/app/.heroku/python/lib/python2.7/site-packages/django/contrib/auth/models.py", line 48, in <module>
2014-02-04T00:32:51.455386+00:00 app[web.1]:     new_class.add_to_class('_meta', Options(meta, **kwargs))
2014-02-04T00:32:51.455231+00:00 app[web.1]:     module = import_module(module_path)
2014-02-04T00:32:51.455386+00:00 app[web.1]:   File "/app/.heroku/python/lib/python2.7/site-packages/django/db/models/base.py", line 96, in __new__
2014-02-04T00:32:51.455799+00:00 app[web.1]:   File "/app/.heroku/python/lib/python2.7/site-packages/django/db/backends/postgresql_psycopg2/base.py", line 25, in <module>
2014-02-04T00:32:51.455386+00:00 app[web.1]:   File "/app/.heroku/python/lib/python2.7/site-packages/django/db/utils.py", line 198, in __getitem__
2014-02-04T00:32:51.455799+00:00 app[web.1]:   File "/app/.heroku/python/lib/python2.7/site-packages/django/utils/importlib.py", line 40, in import_module
2014-02-04T00:32:51.455799+00:00 app[web.1]:     __import__(name)
2014-02-04T00:32:51.455799+00:00 app[web.1]: ImproperlyConfigured: Error loading psycopg2 module: No module named psycopg2
2014-02-04T00:32:51.455386+00:00 app[web.1]:     return getattr(connections[DEFAULT_DB_ALIAS], item)
2014-02-04T00:32:51.455386+00:00 app[web.1]:     backend = load_backend(db['ENGINE'])
2014-02-04T00:32:51.455799+00:00 app[web.1]:   File "/app/.heroku/python/lib/python2.7/site-packages/django/db/utils.py", line 113, in load_backend
2014-02-04T00:32:51.455386+00:00 app[web.1]:   File "/app/.heroku/python/lib/python2.7/site-packages/django/db/models/base.py", line 264, in add_to_class
2014-02-04T00:32:51.455799+00:00 app[web.1]:     raise ImproperlyConfigured("Error loading psycopg2 module: %s" % e)
2014-02-04T00:32:51.455799+00:00 app[web.1]:     return import_module('%s.base' % backend_name)
